<mujoco model="K1">
  <!--
    Vendored from BoosterRobotics/booster_assets (BSD-3-Clause), commit
    486da0f864016676de6dab724fd60a8a551655d1, robots/K1/K1_22dof.xml.
    See VENDORED.md for full provenance. Local modifications made for the
    NUSim (see VENDORED.md "Local modifications" for detail):
      1. Converted the trunk's `<joint type="free">` root into an explicit
         `<freejoint name="root"/>` (upstream already rooted the trunk with a
         free joint; this just names it and uses the canonical MJCF idiom).
      2. Removed worldbody scene dressing (skybox texture, checker
         "texplane" texture + "matplane" material, the "ground" plane geom,
         and the two ad-hoc worldbody lights) so this file is a pure robot
         (body tree + assets + actuator + sensor + default) that can be
         <include>-d into a scene file without a duplicate floor/lighting.
      3. Added <accelerometer> and <velocimeter> sensors on the "imu" site,
         alongside the upstream framequat + gyro.
      4. Added a <keyframe> section with "ready", "lying_front" and
         "lying_back" poses for spawning/getup testing.
      5. Raised the 12 leg motor forceranges to the Booster actuator catalog
         effort limits used by the mujoco_playground K1 training model
         (hip pitch/roll/yaw 68/76/38.3, knee 112, ankle 38.3 N*m) so the RL
         walk policy is not torque-clamped below what it trained with.
  -->
  <compiler angle="radian" meshdir="meshes/" autolimits="true"/>

  <option timestep="0.001" tolerance="1e-6" impratio="10" solver="Newton"/>
  <default>
    <geom solimp="0.90 0.95 0.001" solref="0.001 1"/>
  </default>

  <asset>
    <mesh name="Trunk" file="Trunk.STL"/>
    <mesh name="K1logo" file="K1logo.STL"/>
    <mesh name="Head_1" file="Head_1.STL"/>
    <mesh name="Head_2" file="Head_2.STL"/>
    <mesh name="Left_Arm_1" file="Left_Arm_1.STL"/>
    <mesh name="Left_Arm_2" file="Left_Arm_2.STL"/>
    <mesh name="Left_Arm_3" file="Left_Arm_3.STL"/>
    <mesh name="Left_Arm_4" file="Left_Arm_4.STL"/>
    <mesh name="Right_Arm_1" file="Right_Arm_1.STL"/>
    <mesh name="Right_Arm_2" file="Right_Arm_2.STL"/>
    <mesh name="Right_Arm_3" file="Right_Arm_3.STL"/>
    <mesh name="Right_Arm_4" file="Right_Arm_4.STL"/>
    <mesh name="Left_Hip_Pitch" file="Left_Hip_Pitch.STL"/>
    <mesh name="Left_Hip_Roll" file="Left_Hip_Roll.STL"/>
    <mesh name="Left_Hip_Yaw" file="Left_Hip_Yaw.STL"/>
    <mesh name="Left_Shank" file="Left_Shank.STL"/>
    <mesh name="Left_Ankle_Cross" file="Left_Ankle_Cross.STL"/>
    <mesh name="Left_Foot" file="Left_Foot.STL"/>
    <mesh name="Right_Hip_Pitch" file="Right_Hip_Pitch.STL"/>
    <mesh name="Right_Hip_Roll" file="Right_Hip_Roll.STL"/>
    <mesh name="Right_Hip_Yaw" file="Right_Hip_Yaw.STL"/>
    <mesh name="Right_Shank" file="Right_Shank.STL"/>
    <mesh name="Right_Ankle_Cross" file="Right_Ankle_Cross.STL"/>
    <mesh name="Right_Foot" file="Right_Foot.STL"/>
  </asset>

  <worldbody>
    <body name="Trunk" pos="0 0 1.0">
      <freejoint name="root"/>
      <site name='imu' size='0.01' pos='0.0 0.0 0.0' />
      <inertial pos="-0.0043392 -0.00065534 0.065686" quat="0.999896 -0.00411546 0.0137413 -0.00168959" mass="6.5" diaginertia="0.0962166 0.0895166 0.0201248"/>
      <geom type="mesh" contype="0" conaffinity="0" group="1" density="0" rgba="0.92 0.92 0.93 1" mesh="Trunk"/>
      <!-- <geom type="mesh" rgba="0.92 0.92 0.93 1" mesh="Trunk"/> -->
      <geom size="0.06 0.08 0.1" pos="0 0 0.1" type="box" rgba="0.92 0.92 0.93 0.0"/>
      <geom size="0.05 0.05" pos="0 0 -0.06" quat="0.707105 0.707108 0 0" type="cylinder" rgba="0.92 0.92 0.93 1"/>
      <geom type="mesh" contype="0" conaffinity="0" group="1" density="0" rgba="0.792156862745098 0.819607843137255 0.933333333333333 1" mesh="K1logo"/>
      <body name="Head_1" pos="0.0056 0 0.2149">
        <inertial pos="-0.00069503 -0.00038527 0.031688" quat="0.993827 -0.00957801 0.00894723 -0.110168" mass="0.3" diaginertia="0.000429546 0.000420659 0.000125795"/>
        <joint name="AAHead_yaw" pos="0 0 0" axis="0 0 1" range="-1 1" armature="0.002"/>
        <geom type="mesh" contype="0" conaffinity="0" group="1" density="0" rgba="0.92 0.92 0.93 1" mesh="Head_1"/>
        <geom type="mesh" rgba="0.92 0.92 0.93 1" mesh="Head_1"/>
        <body name="Head_2" pos="0 0 0.033">
          <inertial pos="0.011042 -0.00092871 0.080698" quat="0.996402 -0.00118413 -0.0779414 -0.0332651" mass="0.7" diaginertia="0.00603249 0.00577511 0.0017024"/>
          <joint name="Head_pitch" pos="0 0 0" axis="0 1 0" range="-0.349 0.855" armature="0.002"/>
          <geom type="mesh" contype="0" conaffinity="0" group="1" density="0" rgba="0.12 0.12 0.13 1" mesh="Head_2"/>
          <geom type="mesh" rgba="0.92 0.92 0.93 1" mesh="Head_2"/>
          <!--
            WS-Camera: head RGB camera for module::Camera's offscreen render ->
            NUbots K1Camera shared-memory bridge (config/camera.yaml). Mounted
            just in front of the Head_2 face mesh (front face vertices reach
            x~=0.063 at this height; verified via the mesh's own STL bounds),
            centred laterally (y=0) at the vertical mid-point of the front face
            plate (z~=0.089, mesh z-range there is [0.049, 0.129]). xyaxes picks
            the camera's local X/Y axes directly in the Head_2 (=body, at head
            yaw/pitch=0) frame: X=(0,-1,0) is image-right = the robot's right
            (left is +Y here), Y=(0,0,1) is image-up = world-up when the head is
            level; the implied Z = X x Y = (-1,0,0) puts the view direction
            (-Z) at body +X, i.e. straight ahead -- this repo's own convention,
            confirmed three ways: the kickoff keyframe's comment ("rotation 0
            => facing +x"), the feet's toe-forward geometry (foot box offset
            +x), and Left/Right arm y-signs (left=+y). fovy=70 (vertical) gives
            a ~86 deg horizontal FOV at 4:3 -- a modest, ZED-mini-ish wide view;
            verified level/forward with an offscreen render (host MuJoCo, EGL)
            of this exact camera at the "ready" keyframe: horizon centred,
            floor/sky split behaves exactly as predicted from cam_xpos/cam_xmat.
          -->
          <camera name="head" pos="0.075 0 0.089" xyaxes="0 -1 0  0 0 1" fovy="70"/>
        </body>
      </body>
      <body name="Left_Arm_1" pos="0 0.077 0.1845">
        <inertial pos="-0.002701 0.062383 -0.011965" quat="0.578658 0.689818 -0.347436 0.261905" mass="0.5" diaginertia="0.00223871 0.00217107 0.000254225"/>
        <joint name="ALeft_Shoulder_Pitch" pos="0 0 0" axis="0 1 0" range="-3.316 1.22" armature="0.001"/>
        <geom type="mesh" contype="0" conaffinity="0" group="1" density="0" rgba="0.92 0.92 0.93 1" mesh="Left_Arm_1"/>
        <body name="Left_Arm_2" pos="0.0025 0.068 -0.0135">
          <inertial pos="0.01729 0.018221 -4.329e-05" quat="0.413453 0.573635 -0.413453 0.573635" mass="0.09" diaginertia="0.000113 9.5e-05 6.5e-05"/>
          <joint name="Left_Shoulder_Roll" pos="0 0 0" axis="1 0 0" range="-1.74 1.57" armature="0.001"/>
          <geom type="mesh" contype="0" conaffinity="0" group="1" density="0" rgba="0.92 0.92 0.93 1" mesh="Left_Arm_2"/>
          <geom size="0.035 0.034" pos="-0.007 0 0" quat="0.707105 0 0.707108 0" type="cylinder" rgba="0.92 0.92 0.93 1"/>
          <body name="Left_Arm_3" pos="0 0.044428 0">
            <inertial pos="-0.0003979 0.072617 -0.00066218" quat="0.679502 0.689551 0.177403 -0.176989" mass="0.8" diaginertia="0.00606947 0.00606767 0.000385851"/>
            <joint name="Left_Elbow_Pitch" pos="0 0 0" axis="0 1 0" range="-2.27 2.27" armature="0.001"/>
            <geom type="mesh" contype="0" conaffinity="0" group="1" density="0" rgba="0.92 0.92 0.93 1" mesh="Left_Arm_3"/>
            <geom type="mesh" rgba="0.92 0.92 0.93 1" mesh="Left_Arm_3"/>
            <body name="left_hand_link" pos="0 0.1215 0">
              <inertial pos="-0.0015751 0.084637 0.0087033" quat="0.712106 0.700961 0.0264125 -0.0293496" mass="0.19" diaginertia="0.00205619 0.00202933 8.1482e-05"/>
              <joint name="Left_Elbow_Yaw" pos="0 0 0" axis="0 0 1" range="-2.44 0" armature="0.001"/>
              <geom type="mesh" contype="0" conaffinity="0" group="1" density="0" rgba="0.92 0.92 0.93 1" mesh="Left_Arm_4"/>
              <geom type="mesh" rgba="0.92 0.92 0.93 1" mesh="Left_Arm_4"/>
            </body>
          </body>
        </body>
      </body>
      <body name="Right_Arm_1" pos="0 -0.077 0.1845">
        <inertial pos="-0.0026302 -0.06251 -0.01199" quat="0.689302 0.577958 -0.263425 0.348475" mass="0.5" diaginertia="0.00224439 0.00217742 0.000255199"/>
        <joint name="ARight_Shoulder_Pitch" pos="0 0 0" axis="0 1 0" range="-3.316 1.22" armature="0.001"/>
        <geom type="mesh" contype="0" conaffinity="0" group="1" density="0" rgba="0.92 0.92 0.93 1" mesh="Right_Arm_1"/>
        <body name="Right_Arm_2" pos="0.0025 -0.068 -0.0135">
          <inertial pos="0.017229 -0.018428 4.3784e-05" quat="0.573635 0.413453 -0.573635 0.413453" mass="0.09" diaginertia="0.000113 9.5e-05 6.5e-05"/>
          <joint name="Right_Shoulder_Roll" pos="0 0 0" axis="1 0 0" range="-1.57 1.74" armature="0.001"/>
          <geom type="mesh" contype="0" conaffinity="0" group="1" density="0" rgba="0.92 0.92 0.93 1" mesh="Right_Arm_2"/>
          <geom size="0.035 0.034" pos="-0.007 0 0" quat="0.707105 0 0.707108 0" type="cylinder" rgba="0.92 0.92 0.93 1"/>
          <body name="Right_Arm_3" pos="0 -0.044428 0">
            <inertial pos="-0.00039919 -0.072601 -0.00065629" quat="0.689551 0.679502 0.176989 -0.177403" mass="0.8" diaginertia="0.00607047 0.00606867 0.000386851"/>
            <joint name="Right_Elbow_Pitch" pos="0 0 0" axis="0 1 0" range="-2.27 2.27" armature="0.001"/>
            <geom type="mesh" contype="0" conaffinity="0" group="1" density="0" rgba="0.92 0.92 0.93 1" mesh="Right_Arm_3"/>
            <geom type="mesh" rgba="0.92 0.92 0.93 1" mesh="Right_Arm_3"/>
            <body name="right_hand_link" pos="0 -0.1215 0">
              <inertial pos="-0.0015177 -0.084536 0.0086733" quat="0.700925 0.712091 0.0296562 -0.0274245" mass="0.19" diaginertia="0.00205618 0.00203032 8.14943e-05"/>
              <joint name="Right_Elbow_Yaw" pos="0 0 0" axis="0 0 1" range="0 2.44" armature="0.001"/>
              <geom type="mesh" contype="0" conaffinity="0" group="1" density="0" rgba="0.92 0.92 0.93 1" mesh="Right_Arm_4"/>
              <geom type="mesh" rgba="0.92 0.92 0.93 1" mesh="Right_Arm_4"/>
            </body>
          </body>
        </body>
      </body>
      <body name="Left_Hip_Pitch" pos="0 0.096 -0.077">
        <inertial pos="-0.010093 -0.0019934 -0.024713" quat="0.704206 -0.178798 -0.198986 0.65767" mass="0.69" diaginertia="0.000987585 0.000880963 0.000503452"/>
        <joint name="Left_Hip_Pitch" pos="0 0 0" axis="0 1 0" range="-3 2.21" armature="0.0478125"/>
        <geom type="mesh" contype="0" conaffinity="0" group="1" density="0" rgba="0.92 0.92 0.93 1" mesh="Left_Hip_Pitch"/>
        <body name="Left_Hip_Roll" pos="0 0 -0.026">
          <inertial pos="0.023585 4.9e-05 -0.024996" quat="0.677218 0.203412 0.203412 0.677218" mass="0.13" diaginertia="0.000262 0.000222694 0.000118306"/>
          <joint name="Left_Hip_Roll" pos="0 0 0" axis="1 0 0" range="-0.4 1.57" armature="0.0339552"/>
          <geom type="mesh" contype="0" conaffinity="0" group="1" density="0" rgba="0.92 0.92 0.93 1" mesh="Left_Hip_Roll"/>
          <geom size="0.036 0.047" quat="0.707105 0 0.707108 0" type="cylinder" rgba="0.92 0.92 0.93 1"/>
          <body name="Left_Hip_Yaw" pos="0.012 0 -0.0485">
            <inertial pos="-0.0084744 -0.0040494 -0.087906" quat="0.857995 -0.00590801 -0.0582713 0.510308" mass="1.65" diaginertia="0.0162716 0.0158564 0.00134895"/>
            <joint name="Left_Hip_Yaw" pos="0 0 0" axis="0 0 1" range="-1 1" armature="0.0282528"/>
            <geom type="mesh" contype="0" conaffinity="0" group="1" density="0" rgba="0.92 0.92 0.93 1" mesh="Left_Hip_Yaw"/>
            <geom size="0.04 0.033" pos="0 0 -0.03" type="cylinder" rgba="0.92 0.92 0.93 1"/>
            <body name="Left_Shank" pos="-0.014 0 -0.117">
              <inertial pos="-0.00081083 0.0031459 -0.10922" quat="0.940563 -0.00388906 -0.00385774 0.339574" mass="1.5" diaginertia="0.0237114 0.0236423 0.00123731"/>
              <joint name="Left_Knee_Pitch" pos="0 0 0" axis="0 1 0" range="0 2.23" armature="0.095625"/>
              <geom type="mesh" contype="0" conaffinity="0" group="1" density="0" rgba="0.92 0.92 0.93 1" mesh="Left_Shank"/>
              <geom size="0.045 0.035" quat="0.707105 0.707108 0 0" type="cylinder" rgba="0.92 0.92 0.93 1"/>
              <geom size="0.03 0.03 0.05" pos="0 0 -0.13" type="box" rgba="0.92 0.92 0.93 1"/>
              <body name="Left_Ankle_Cross" pos="0.00019706 0.0002 -0.24519">
                <inertial pos="0 0 0" quat="0.5 0.5 0.5 0.5" mass="0.039" diaginertia="4e-06 4e-06 2e-06"/>
                <joint name="Left_Ankle_Pitch" pos="0 0 0" axis="0 1 0" range="-0.87 0.345" armature="0.0565"/>
                <geom type="mesh" contype="0" conaffinity="0" group="1" density="0" rgba="0.92 0.92 0.93 1" mesh="Left_Ankle_Cross"/>
                <body name="left_foot_link">
                  <inertial pos="0.011662 0.000244 -0.014364" quat="-0.00144487 0.663983 -0.00148176 0.747745" mass="0.494" diaginertia="0.0012267 0.00117 0.000247305"/>
                  <joint name="Left_Ankle_Roll" pos="0 0 0" axis="1 0 0" range="-0.345 0.345" armature="0.0565"/>
                  <geom type="mesh" contype="0" conaffinity="0" group="1" density="0" rgba="0.75294 0.75294 0.75294 1.0" mesh="Left_Foot"/>
                  <!-- <geom type="mesh" rgba="0.92 0.92 0.93 1" mesh="Left_Foot" friction="0.1 0.005 0.0001"/> -->
                  <geom type="box" pos="0.026 0 -0.02" size="0.09 0.035 0.018" rgba="0.92 0.92 0.93 0.0"/>
                </body>
              </body>
            </body>
          </body>
        </body>
      </body>
      <body name="Right_Hip_Pitch" pos="0 -0.096 -0.077">
        <inertial pos="-0.010065 0.0020086 -0.024739" quat="0.656712 -0.199052 -0.176963 0.705544" mass="0.69" diaginertia="0.000988671 0.000880749 0.00050458"/>
        <joint name="Right_Hip_Pitch" pos="0 0 0" axis="0 1 0" range="-3 2.21" armature="0.0478125"/>
        <geom type="mesh" contype="0" conaffinity="0" group="1" density="0" rgba="0.92 0.92 0.93 1" mesh="Right_Hip_Pitch"/>
        <body name="Right_Hip_Roll" pos="0 0 -0.026">
          <inertial pos="0.023585 4.9e-05 -0.024996" quat="0.677218 0.203412 0.203412 0.677218" mass="0.13" diaginertia="0.000262 0.000222694 0.000118306"/>
          <joint name="Right_Hip_Roll" pos="0 0 0" axis="1 0 0" range="-1.57 0.4" armature="0.0339552"/>
          <geom type="mesh" contype="0" conaffinity="0" group="1" density="0" rgba="0.92 0.92 0.93 1" mesh="Right_Hip_Roll"/>
          <geom size="0.036 0.047" quat="0.707105 0 0.707108 0" type="cylinder" rgba="0.92 0.92 0.93 1"/>
          <body name="Right_Hip_Yaw" pos="0.012 0 -0.0485">
            <inertial pos="-0.008475 0.0040392 -0.087906" quat="0.510308 -0.0582713 -0.00590801 0.857995" mass="1.65" diaginertia="0.0162716 0.0158564 0.00134895"/>
            <joint name="Right_Hip_Yaw" pos="0 0 0" axis="0 0 1" range="-1 1" armature="0.0282528"/>
            <geom type="mesh" contype="0" conaffinity="0" group="1" density="0" rgba="0.92 0.92 0.93 1" mesh="Right_Hip_Yaw"/>
            <geom size="0.04 0.033" pos="0 0 -0.03" type="cylinder" rgba="0.92 0.92 0.93 1"/>
            <body name="Right_Shank" pos="-0.014 0 -0.117">
              <inertial pos="-0.000805 -0.003146 -0.109215" quat="0.940537 0.00388176 -0.00383651 -0.339646" mass="1.5" diaginertia="0.0237114 0.0236423 0.00123733"/>
              <joint name="Right_Knee_Pitch" pos="0 0 0" axis="0 1 0" range="0 2.23" armature="0.095625"/>
              <geom type="mesh" contype="0" conaffinity="0" group="1" density="0" rgba="0.92 0.92 0.93 1" mesh="Right_Shank"/>
              <geom size="0.045 0.035" quat="0.707105 0.707108 0 0" type="cylinder" rgba="0.92 0.92 0.93 1"/>
              <geom size="0.03 0.03 0.05" pos="0 0 -0.13" type="box" rgba="0.92 0.92 0.93 1"/>
              <body name="Right_Ankle_Cross" pos="0.00019706 -0.0002 -0.24519">
                <inertial pos="0 0 0" quat="0.5 0.5 0.5 0.5" mass="0.039" diaginertia="4e-06 4e-06 2e-06"/>
                <joint name="Right_Ankle_Pitch" pos="0 0 0" axis="0 1 0" range="-0.87 0.345" armature="0.0565"/>
                <geom type="mesh" contype="0" conaffinity="0" group="1" density="0" rgba="0.92 0.92 0.93 1" mesh="Right_Ankle_Cross"/>
                <body name="right_foot_link">
                  <inertial pos="0.011662 -0.000244 -0.014364" quat="0.00144487 0.663983 0.00148176 0.747745" mass="0.494" diaginertia="0.0012267 0.00117 0.000247305"/>
                  <joint name="Right_Ankle_Roll" pos="0 0 0" axis="1 0 0" range="-0.345 0.345" armature="0.0565"/>
                  <geom type="mesh" contype="0" conaffinity="0" group="1" density="0" rgba="0.75294 0.75294 0.75294 1.0" mesh="Right_Foot"/>
                  <!-- <geom type="mesh" rgba="0.92 0.92 0.93 1" mesh="Right_Foot" friction="0.1 0.005 0.0001"/> -->
                  <geom type="box" pos="0.026 0 -0.02" size="0.09 0.035 0.018" rgba="0.92 0.92 0.93 0.0"/>
                </body>
              </body>
            </body>
          </body>
        </body>
      </body>
    </body>
  </worldbody>
  <actuator>
    <motor name="AAHead_yaw" joint="AAHead_yaw" forcerange="-6.0 6.0"/>
    <motor name="Head_pitch" joint="Head_pitch" forcerange="-6.0 6.0"/>
    <motor name="ALeft_Shoulder_Pitch" joint="ALeft_Shoulder_Pitch" forcerange="-14.0 14.0"/>
    <motor name="Left_Shoulder_Roll" joint="Left_Shoulder_Roll" forcerange="-14.0 14.0"/>
    <motor name="Left_Elbow_Pitch" joint="Left_Elbow_Pitch" forcerange="-14.0 14.0"/>
    <motor name="Left_Elbow_Yaw" joint="Left_Elbow_Yaw" forcerange="-14.0 14.0"/>
    <motor name="ARight_Shoulder_Pitch" joint="ARight_Shoulder_Pitch" forcerange="-14.0 14.0"/>
    <motor name="Right_Shoulder_Roll" joint="Right_Shoulder_Roll" forcerange="-14.0 14.0"/>
    <motor name="Right_Elbow_Pitch" joint="Right_Elbow_Pitch" forcerange="-14.0 14.0"/>
    <motor name="Right_Elbow_Yaw" joint="Right_Elbow_Yaw" forcerange="-14.0 14.0"/>
    <motor name="Left_Hip_Pitch" joint="Left_Hip_Pitch" forcerange="-68.0 68.0"/>
    <motor name="Left_Hip_Roll" joint="Left_Hip_Roll" forcerange="-76.0 76.0"/>
    <motor name="Left_Hip_Yaw" joint="Left_Hip_Yaw" forcerange="-38.3 38.3"/>
    <motor name="Left_Knee_Pitch" joint="Left_Knee_Pitch" forcerange="-112.0 112.0"/>
    <motor name="Left_Ankle_Pitch" joint="Left_Ankle_Pitch" forcerange="-38.3 38.3"/>
    <motor name="Left_Ankle_Roll" joint="Left_Ankle_Roll" forcerange="-38.3 38.3"/>
    <motor name="Right_Hip_Pitch" joint="Right_Hip_Pitch" forcerange="-68.0 68.0"/>
    <motor name="Right_Hip_Roll" joint="Right_Hip_Roll" forcerange="-76.0 76.0"/>
    <motor name="Right_Hip_Yaw" joint="Right_Hip_Yaw" forcerange="-38.3 38.3"/>
    <motor name="Right_Knee_Pitch" joint="Right_Knee_Pitch" forcerange="-112.0 112.0"/>
    <motor name="Right_Ankle_Pitch" joint="Right_Ankle_Pitch" forcerange="-38.3 38.3"/>
    <motor name="Right_Ankle_Roll" joint="Right_Ankle_Roll" forcerange="-38.3 38.3"/>
  </actuator>
  <sensor>
    <framequat name="orientation" objtype="site" noise="0.001" objname="imu" />
    <gyro name="angular-velocity" site="imu" noise="0.005" />
    <accelerometer name="acceleration" site="imu" noise="0.01"/>
    <velocimeter name="linear-velocity" site="imu" noise="0.01"/>
  </sensor>

  <keyframe>
    <!--
      qpos layout: [x y z qw qx qy qz] (free "root" joint) followed by the
      22 hinge joints in body-tree order, which is identical to JointIndexK1
      order (head yaw/pitch, L arm x4, R arm x4, L leg x6, R leg x6) --
      see mujoco/shared/k1/JointIndex.hpp. Heights/orientations were derived
      from this mesh's actual collision geometry (not assumed) and verified
      in simulation (mj_step x500 from each key) to settle without the base
      jumping/exploding -- see VENDORED.md "Local modifications" for the
      settle-test methodology and measured results. ctrl is left at the
      MuJoCo default (0 torque) since the actuators are direct-torque
      <motor> elements, not position servos; joint targets for a PD
      controller are supplied externally (module/Simulation + gains.yaml).
    -->
    <key name="ready"
         qpos="0 0 0.555 1 0 0 0
               0 0
               0 -1.3 0 0
               0 1.3 0 0
               0 0 0 0 0 0
               0 0 0 0 0 0"/>
    <key name="lying_front"
         qpos="0 0 0.075 0.707107 0 0.707107 0
               0 0
               0.15 0 0.3 0
               0.15 0 0.3 0
               0.15 0 0 0.3 -0.15 0
               0.15 0 0 0.3 -0.15 0"/>
    <key name="lying_back"
         qpos="0 0 0.066 0.707107 0 -0.707107 0
               0 0
               -0.15 0 0.15 0
               -0.15 0 0.15 0
               -0.15 0 0 0.15 0.075 0
               -0.15 0 0 0.15 0.075 0"/>
  </keyframe>

</mujoco>
